<sdf version='1.7'>
  <world name='bfmc_official'>
    <gravity>0 0 -9.8</gravity>
    <light name='c1' type='point'>
      <pose>0 0 2 0 -0 0</pose>
      <diffuse>125 125 125 125</diffuse>
      <specular>125 125 125 125</specular>
      <attenuation>
        <range>20</range>
        <constant>0.3</constant>
        <quadratic>0</quadratic>
        <linear>0</linear>
      </attenuation>
      <cast_shadows>0</cast_shadows>
      <direction>0 0 -1</direction>
      <spot>
        <inner_angle>0</inner_angle>
        <outer_angle>0</outer_angle>
        <falloff>0</falloff>
      </spot>
    </light>
    <light name='c2' type='point'>
      <pose>15 0 2 0 -0 0</pose>
      <diffuse>125 125 125 125</diffuse>
      <specular>125 125 125 125</specular>
      <attenuation>
        <range>20</range>
        <constant>0.3</constant>
        <quadratic>0</quadratic>
        <linear>0</linear>
      </attenuation>
      <cast_shadows>0</cast_shadows>
      <direction>0 0 -1</direction>
      <spot>
        <inner_angle>0</inner_angle>
        <outer_angle>0</outer_angle>
        <falloff>0</falloff>
      </spot>
    </light>
    <light name='c3' type='point'>
      <pose>0 -15 2 0 -0 0</pose>
      <diffuse>125 125 125 125</diffuse>
      <specular>125 125 125 125</specular>
      <attenuation>
        <range>20</range>
        <constant>0.3</constant>
        <quadratic>0</quadratic>
        <linear>0</linear>
      </attenuation>
      <cast_shadows>0</cast_shadows>
      <direction>0 0 -1</direction>
      <spot>
        <inner_angle>0</inner_angle>
        <outer_angle>0</outer_angle>
        <falloff>0</falloff>
      </spot>
    </light>
    <light name='c4' type='point'>
      <pose>15 -15 2 0 -0 0</pose>
      <diffuse>125 125 125 125</diffuse>
      <specular>125 125 125 125</specular>
      <attenuation>
        <range>50</range>
        <constant>0.3</constant>
        <quadratic>0</quadratic>
        <linear>0</linear>
      </attenuation>
      <cast_shadows>0</cast_shadows>
      <direction>0 0 -1</direction>
      <spot>
        <inner_angle>0</inner_angle>
        <outer_angle>0</outer_angle>
        <falloff>0</falloff>
      </spot>
    </light>
    <model name='track'>
      <static>1</static>
      <link name='link'>
        <collision name='collision'>
          <geometry>
            <plane>
              <normal>0 0 1</normal>
              <size>20.68 13.74</size>
            </plane>
          </geometry>
          <surface>
            <contact>
              <collide_bitmask>65535</collide_bitmask>
              <ode/>
            </contact>
            <friction>
              <ode>
                <mu>1</mu>
                <mu2>1</mu2>
              </ode>
              <torsional>
                <ode/>
              </torsional>
            </friction>
            <bounce/>
          </surface>
          <max_contacts>10</max_contacts>
        </collision>
        <visual name='visual'>
          <cast_shadows>1</cast_shadows>
          <transparency>0</transparency>
          <geometry>
            <plane>
              <normal>0 0 1</normal>
              <size>20.68 13.74</size>
            </plane>
          </geometry>
          <material>
            <ambient>1 1 1 1</ambient>
            <diffuse>1 1 1 1</diffuse>
            <specular>0 0 0 0</specular>
            <emissive>1 1 1 1</emissive>
            <script>
              <uri>model://track/materials/scripts</uri>
              <uri>model://track/materials/textures</uri>
              <name>BFMC_MATERIAL</name>
            </script>
          </material>
        </visual>
        <self_collide>0</self_collide>
        <enable_wind>0</enable_wind>
        <kinematic>0</kinematic>
      </link>
      <pose>10.34 6.87 0 0 -0 0</pose>
    </model>
    <magnetic_field>6e-06 2.3e-05 -4.2e-05</magnetic_field>
    <atmosphere type='adiabatic'/>
    <physics type='ode'>
      <max_step_size>0.001</max_step_size>
      <real_time_factor>1</real_time_factor>
      <real_time_update_rate>1000</real_time_update_rate>
    </physics>
    <scene>
      <ambient>0.4 0.4 0.4 1</ambient>
      <background>0.7 0.7 0.7 1</background>
      <shadows>1</shadows>
    </scene>
    <wind/>
    <spherical_coordinates>
      <surface_model>EARTH_WGS84</surface_model>
      <latitude_deg>0</latitude_deg>
      <longitude_deg>0</longitude_deg>
      <elevation>0</elevation>
      <heading_deg>0</heading_deg>
    </spherical_coordinates>
    <model name='automobile'>
      <frame name='chassis::__model__' attached_to='chassis::link'>
        <pose relative_to='__model__'>0 0 0 0 -0 0</pose>
      </frame>
      <link name='chassis::link'>
        <inertial>
          <mass>0.26244</mass>
          <inertia>
            <ixx>0.00283444</ixx>
            <ixy>0</ixy>
            <ixz>0</ixz>
            <iyy>0.00039867</iyy>
            <iyz>0</iyz>
            <izz>0.00323293</izz>
          </inertia>
          <pose>0 0 0 0 -0 0</pose>
        </inertial>
        <pose relative_to='chassis::__model__'>0 0 0 0 -0 0</pose>
        <gravity>1</gravity>
        <kinematic>0</kinematic>
        <enable_wind>0</enable_wind>
        <visual name='visual'>
          <pose>0 0 -0.0065 0 -0 0</pose>
          <geometry>
            <mesh>
              <uri>model://chassis/meshes/chassisV5.dae</uri>
              <scale>1 1 1</scale>
            </mesh>
          </geometry>
          <material>
            <lighting>1</lighting>
            <shader type='vertex'>
              <normal_map>__default__</normal_map>
            </shader>
            <ambient>0.6 0.6 0.6 1</ambient>
            <diffuse>0.85 0.85 0.85 1</diffuse>
            <specular>0.6 0.6 0.6 1</specular>
            <emissive>0 0 0 1</emissive>
          </material>
          <transparency>0</transparency>
          <cast_shadows>1</cast_shadows>
        </visual>
        <collision name='collision'>
          <laser_retro>0</laser_retro>
          <max_contacts>10</max_contacts>
          <pose>0 0 0 0 -0 0</pose>
          <geometry>
            <box>
              <size>0.135 0.36 0.002</size>
            </box>
          </geometry>
          <surface>
            <friction>
              <ode>
                <mu>1</mu>
                <mu2>1</mu2>
                <fdir1>0 0 0</fdir1>
                <slip1>0</slip1>
                <slip2>0</slip2>
              </ode>
              <torsional>
                <coefficient>1</coefficient>
                <patch_radius>0</patch_radius>
                <surface_radius>0</surface_radius>
                <use_patch_radius>1</use_patch_radius>
                <ode>
                  <slip>0</slip>
                </ode>
              </torsional>
            </friction>
            <bounce>
              <restitution_coefficient>0</restitution_coefficient>
              <threshold>1e+06</threshold>
            </bounce>
            <contact>
              <collide_without_contact>0</collide_without_contact>
              <collide_without_contact_bitmask>1</collide_without_contact_bitmask>
              <collide_bitmask>1</collide_bitmask>
              <ode>
                <soft_cfm>0</soft_cfm>
                <soft_erp>0.2</soft_erp>
                <kp>1e+13</kp>
                <kd>1</kd>
                <max_vel>0.01</max_vel>
                <min_depth>0</min_depth>
              </ode>
              <bullet>
                <split_impulse>1</split_impulse>
                <split_impulse_penetration_threshold>-0.01</split_impulse_penetration_threshold>
                <soft_cfm>0</soft_cfm>
                <soft_erp>0.2</soft_erp>
                <kp>1e+13</kp>
                <kd>1</kd>
              </bullet>
            </contact>
          </surface>
        </collision>
        <self_collide>0</self_collide>
      </link>
      <frame name='wheel_rear_left::__model__' attached_to='wheel_rear_left::link_rim'>
        <pose relative_to='__model__'>-0.152 0.081 0 0 -0 0</pose>
      </frame>
      <link name='wheel_rear_left::link_rim'>
        <inertial>
          <mass>0.038</mass>
          <inertia>
            <ixx>1.283e-05</ixx>
            <ixy>0</ixy>
            <ixz>0</ixz>
            <iyy>1.283e-05</iyy>
            <iyz>0</iyz>
            <izz>2.069e-05</izz>
          </inertia>
          <pose>0 0 0 0 -0 0</pose>
        </inertial>
        <pose relative_to='wheel_rear_left::__model__'>0 0 0 1.5708 -0 0</pose>
        <gravity>1</gravity>
        <kinematic>0</kinematic>
        <enable_wind>0</enable_wind>
        <visual name='visual'>
          <pose>0 0 0 -1.5708 0 0</pose>
          <geometry>
            <mesh>
              <uri>model://wheel_left/meshes/rim.dae</uri>
              <scale>1 1 1</scale>
            </mesh>
          </geometry>
          <material>
            <lighting>1</lighting>
            <shader type='vertex'>
              <normal_map>__default__</normal_map>
            </shader>
            <ambient>0.2 0.2 0.2 1</ambient>
            <diffuse>0.3 0.3 0.3 1</diffuse>
            <specular>0.5 0.5 0.5 1</specular>
            <emissive>0 0 0 0</emissive>
          </material>
          <transparency>0</transparency>
          <cast_shadows>1</cast_shadows>
        </visual>
        <collision name='collision'>
          <laser_retro>0</laser_retro>
          <max_contacts>10</max_contacts>
          <pose>0 0 0 0 -0 0</pose>
          <geometry>
            <cylinder>
              <radius>0.033</radius>
              <length>0.028</length>
            </cylinder>
          </geometry>
          <surface>
            <friction>
              <ode>
                <mu>0.7</mu>
                <mu2>0.7</mu2>
                <fdir1>0 0 0</fdir1>
                <slip1>0</slip1>
                <slip2>0</slip2>
              </ode>
              <torsional>
                <coefficient>1</coefficient>
                <patch_radius>0</patch_radius>
                <surface_radius>0</surface_radius>
                <use_patch_radius>1</use_patch_radius>
                <ode>
                  <slip>0</slip>
                </ode>
              </torsional>
            </friction>
            <bounce>
              <restitution_coefficient>0</restitution_coefficient>
              <threshold>1e+06</threshold>
            </bounce>
            <contact>
              <collide_without_contact>0</collide_without_contact>
              <collide_without_contact_bitmask>1</collide_without_contact_bitmask>
              <collide_bitmask>1</collide_bitmask>
              <ode>
                <soft_cfm>0</soft_cfm>
                <soft_erp>0.2</soft_erp>
                <kp>1e+07</kp>
                <kd>1</kd>
                <max_vel>0.01</max_vel>
                <min_depth>0</min_depth>
              </ode>
              <bullet>
                <split_impulse>1</split_impulse>
                <split_impulse_penetration_threshold>-0.01</split_impulse_penetration_threshold>
                <soft_cfm>0</soft_cfm>
                <soft_erp>0.2</soft_erp>
                <kp>1e+07</kp>
                <kd>1</kd>
              </bullet>
            </contact>
          </surface>
        </collision>
        <self_collide>0</self_collide>
      </link>
      <frame name='wheel_rear_right::__model__' attached_to='wheel_rear_right::link_rim'>
        <pose relative_to='__model__'>-0.152 -0.081 0 0 -0 0</pose>
      </frame>
      <link name='wheel_rear_right::link_rim'>
        <inertial>
          <mass>0.038</mass>
          <inertia>
            <ixx>1.283e-05</ixx>
            <ixy>0</ixy>
            <ixz>0</ixz>
            <iyy>1.283e-05</iyy>
            <iyz>0</iyz>
            <izz>2.069e-05</izz>
          </inertia>
          <pose>0 0 0 0 -0 0</pose>
        </inertial>
        <pose relative_to='wheel_rear_right::__model__'>0 0 0 1.5708 -0 0</pose>
        <gravity>1</gravity>
        <kinematic>0</kinematic>
        <enable_wind>0</enable_wind>
        <visual name='visual'>
          <pose>0 0 0 -1.5708 0 0</pose>
          <geometry>
            <mesh>
              <uri>model://wheel_right/meshes/rim.dae</uri>
              <scale>1 1 1</scale>
            </mesh>
          </geometry>
          <material>
            <lighting>1</lighting>
            <shader type='vertex'>
              <normal_map>__default__</normal_map>
            </shader>
            <ambient>0.2 0.2 0.2 1</ambient>
            <diffuse>0.3 0.3 0.3 1</diffuse>
            <specular>0.5 0.5 0.5 1</specular>
            <emissive>0 0 0 0</emissive>
          </material>
          <transparency>0</transparency>
          <cast_shadows>1</cast_shadows>
        </visual>
        <collision name='collision'>
          <laser_retro>0</laser_retro>
          <max_contacts>10</max_contacts>
          <pose>0 0 0 0 -0 0</pose>
          <geometry>
            <cylinder>
              <radius>0.033</radius>
              <length>0.028</length>
            </cylinder>
          </geometry>
          <surface>
            <friction>
              <ode>
                <mu>0.7</mu>
                <mu2>0.7</mu2>
                <fdir1>0 0 0</fdir1>
                <slip1>0</slip1>
                <slip2>0</slip2>
              </ode>
              <torsional>
                <coefficient>1</coefficient>
                <patch_radius>0</patch_radius>
                <surface_radius>0</surface_radius>
                <use_patch_radius>1</use_patch_radius>
                <ode>
                  <slip>0</slip>
                </ode>
              </torsional>
            </friction>
            <bounce>
              <restitution_coefficient>0</restitution_coefficient>
              <threshold>1e+06</threshold>
            </bounce>
            <contact>
              <collide_without_contact>0</collide_without_contact>
              <collide_without_contact_bitmask>1</collide_without_contact_bitmask>
              <collide_bitmask>1</collide_bitmask>
              <ode>
                <soft_cfm>0</soft_cfm>
                <soft_erp>0.2</soft_erp>
                <kp>1e+07</kp>
                <kd>1</kd>
                <max_vel>0.01</max_vel>
                <min_depth>0</min_depth>
              </ode>
              <bullet>
                <split_impulse>1</split_impulse>
                <split_impulse_penetration_threshold>-0.01</split_impulse_penetration_threshold>
                <soft_cfm>0</soft_cfm>
                <soft_erp>0.2</soft_erp>
                <kp>1e+07</kp>
                <kd>1</kd>
              </bullet>
            </contact>
          </surface>
        </collision>
        <self_collide>0</self_collide>
      </link>
      <frame name='steer_left::__model__' attached_to='steer_left::link_steer'>
        <pose relative_to='__model__'>0.112 0.0725 0 0 -0 0</pose>
      </frame>
      <link name='steer_left::link_steer'>
        <inertial>
          <mass>0.001</mass>
          <inertia>
            <ixx>0.00014583</ixx>
            <ixy>0</ixy>
            <ixz>0</ixz>
            <iyy>0.00014583</iyy>
            <iyz>0</iyz>
            <izz>0.000125</izz>
          </inertia>
          <pose>0 0 0 0 -0 0</pose>
        </inertial>
        <pose relative_to='steer_left::__model__'>0 0 0 1.5708 -0 0</pose>
        <gravity>1</gravity>
        <self_collide>0</self_collide>
        <kinematic>0</kinematic>
        <enable_wind>0</enable_wind>
        <visual name='visual'>
          <pose>0 0 0 0 -0 0</pose>
          <geometry>
            <cylinder>
              <radius>0.001</radius>
              <length>0.01</length>
            </cylinder>
          </geometry>
          <material>
            <lighting>1</lighting>
            <script>
              <uri>file://media/materials/scripts/gazebo.material</uri>
              <name>Gazebo/Grey</name>
            </script>
            <shader type='vertex'>
              <normal_map>__default__</normal_map>
            </shader>
            <ambient>0.3 0.3 0.3 1</ambient>
            <diffuse>0.7 0.7 0.7 1</diffuse>
            <specular>0.01 0.01 0.01 1</specular>
            <emissive>0 0 0 1</emissive>
          </material>
          <transparency>0</transparency>
          <cast_shadows>1</cast_shadows>
        </visual>
        <collision name='collision'>
          <laser_retro>0</laser_retro>
          <max_contacts>10</max_contacts>
          <pose>0 0 0 0 -0 0</pose>
          <geometry>
            <cylinder>
              <radius>0.001</radius>
              <length>0.01</length>
            </cylinder>
          </geometry>
          <surface>
            <friction>
              <ode>
                <mu>1</mu>
                <mu2>1</mu2>
                <fdir1>0 0 0</fdir1>
                <slip1>0</slip1>
                <slip2>0</slip2>
              </ode>
              <torsional>
                <coefficient>1</coefficient>
                <patch_radius>0</patch_radius>
                <surface_radius>0</surface_radius>
                <use_patch_radius>1</use_patch_radius>
                <ode>
                  <slip>0</slip>
                </ode>
              </torsional>
            </friction>
            <bounce>
              <restitution_coefficient>0</restitution_coefficient>
              <threshold>1e+06</threshold>
            </bounce>
            <contact>
              <collide_without_contact>0</collide_without_contact>
              <collide_without_contact_bitmask>1</collide_without_contact_bitmask>
              <collide_bitmask>1</collide_bitmask>
              <ode>
                <soft_cfm>0</soft_cfm>
                <soft_erp>0.2</soft_erp>
                <kp>1e+13</kp>
                <kd>1</kd>
                <max_vel>0.01</max_vel>
                <min_depth>0</min_depth>
              </ode>
              <bullet>
                <split_impulse>1</split_impulse>
                <split_impulse_penetration_threshold>-0.01</split_impulse_penetration_threshold>
                <soft_cfm>0</soft_cfm>
                <soft_erp>0.2</soft_erp>
                <kp>1e+13</kp>
                <kd>1</kd>
              </bullet>
            </contact>
          </surface>
        </collision>
      </link>
      <frame name='steer_right::__model__' attached_to='steer_right::link_steer'>
        <pose relative_to='__model__'>0.112 -0.0725 0 0 -0 0</pose>
      </frame>
      <link name='steer_right::link_steer'>
        <inertial>
          <mass>0.001</mass>
          <inertia>
            <ixx>0.00014583</ixx>
            <ixy>0</ixy>
            <ixz>0</ixz>
            <iyy>0.00014583</iyy>
            <iyz>0</iyz>
            <izz>0.000125</izz>
          </inertia>
          <pose>0 0 0 0 -0 0</pose>
        </inertial>
        <pose relative_to='steer_right::__model__'>0 0 0 1.5708 -0 0</pose>
        <gravity>1</gravity>
        <self_collide>0</self_collide>
        <kinematic>0</kinematic>
        <enable_wind>0</enable_wind>
        <visual name='visual'>
          <pose>0 0 0 0 -0 0</pose>
          <geometry>
            <cylinder>
              <radius>0.001</radius>
              <length>0.01</length>
            </cylinder>
          </geometry>
          <material>
            <lighting>1</lighting>
            <script>
              <uri>file://media/materials/scripts/gazebo.material</uri>
              <name>Gazebo/Grey</name>
            </script>
            <shader type='vertex'>
              <normal_map>__default__</normal_map>
            </shader>
            <ambient>0.3 0.3 0.3 1</ambient>
            <diffuse>0.7 0.7 0.7 1</diffuse>
            <specular>0.01 0.01 0.01 1</specular>
            <emissive>0 0 0 1</emissive>
          </material>
          <transparency>0</transparency>
          <cast_shadows>1</cast_shadows>
        </visual>
        <collision name='collision'>
          <laser_retro>0</laser_retro>
          <max_contacts>10</max_contacts>
          <pose>0 0 0 0 -0 0</pose>
          <geometry>
            <cylinder>
              <radius>0.001</radius>
              <length>0.01</length>
            </cylinder>
          </geometry>
          <surface>
            <friction>
              <ode>
                <mu>1</mu>
                <mu2>1</mu2>
                <fdir1>0 0 0</fdir1>
                <slip1>0</slip1>
                <slip2>0</slip2>
              </ode>
              <torsional>
                <coefficient>1</coefficient>
                <patch_radius>0</patch_radius>
                <surface_radius>0</surface_radius>
                <use_patch_radius>1</use_patch_radius>
                <ode>
                  <slip>0</slip>
                </ode>
              </torsional>
            </friction>
            <bounce>
              <restitution_coefficient>0</restitution_coefficient>
              <threshold>1e+06</threshold>
            </bounce>
            <contact>
              <collide_without_contact>0</collide_without_contact>
              <collide_without_contact_bitmask>1</collide_without_contact_bitmask>
              <collide_bitmask>1</collide_bitmask>
              <ode>
                <soft_cfm>0</soft_cfm>
                <soft_erp>0.2</soft_erp>
                <kp>1e+13</kp>
                <kd>1</kd>
                <max_vel>0.01</max_vel>
                <min_depth>0</min_depth>
              </ode>
              <bullet>
                <split_impulse>1</split_impulse>
                <split_impulse_penetration_threshold>-0.01</split_impulse_penetration_threshold>
                <soft_cfm>0</soft_cfm>
                <soft_erp>0.2</soft_erp>
                <kp>1e+13</kp>
                <kd>1</kd>
              </bullet>
            </contact>
          </surface>
        </collision>
      </link>
      <frame name='wheel_front_left::__model__' attached_to='wheel_front_left::link_rim'>
        <pose relative_to='__model__'>0.118 0.081 0 0 -0 0</pose>
      </frame>
      <link name='wheel_front_left::link_rim'>
        <inertial>
          <mass>0.038</mass>
          <inertia>
            <ixx>1.283e-05</ixx>
            <ixy>0</ixy>
            <ixz>0</ixz>
            <iyy>1.283e-05</iyy>
            <iyz>0</iyz>
            <izz>2.069e-05</izz>
          </inertia>
          <pose>0 0 0 0 -0 0</pose>
        </inertial>
        <pose relative_to='wheel_front_left::__model__'>0 0 0 1.5708 -0 0</pose>
        <gravity>1</gravity>
        <kinematic>0</kinematic>
        <enable_wind>0</enable_wind>
        <visual name='visual'>
          <pose>0 0 0 -1.5708 0 0</pose>
          <geometry>
            <mesh>
              <uri>model://wheel_left/meshes/rim.dae</uri>
              <scale>1 1 1</scale>
            </mesh>
          </geometry>
          <material>
            <lighting>1</lighting>
            <shader type='vertex'>
              <normal_map>__default__</normal_map>
            </shader>
            <ambient>0.2 0.2 0.2 1</ambient>
            <diffuse>0.3 0.3 0.3 1</diffuse>
            <specular>0.5 0.5 0.5 1</specular>
            <emissive>0 0 0 0</emissive>
          </material>
          <transparency>0</transparency>
          <cast_shadows>1</cast_shadows>
        </visual>
        <collision name='collision'>
          <laser_retro>0</laser_retro>
          <max_contacts>10</max_contacts>
          <pose>0 0 0 0 -0 0</pose>
          <geometry>
            <cylinder>
              <radius>0.033</radius>
              <length>0.028</length>
            </cylinder>
          </geometry>
          <surface>
            <friction>
              <ode>
                <mu>0.7</mu>
                <mu2>0.7</mu2>
                <fdir1>0 0 0</fdir1>
                <slip1>0</slip1>
                <slip2>0</slip2>
              </ode>
              <torsional>
                <coefficient>1</coefficient>
                <patch_radius>0</patch_radius>
                <surface_radius>0</surface_radius>
                <use_patch_radius>1</use_patch_radius>
                <ode>
                  <slip>0</slip>
                </ode>
              </torsional>
            </friction>
            <bounce>
              <restitution_coefficient>0</restitution_coefficient>
              <threshold>1e+06</threshold>
            </bounce>
            <contact>
              <collide_without_contact>0</collide_without_contact>
              <collide_without_contact_bitmask>1</collide_without_contact_bitmask>
              <collide_bitmask>1</collide_bitmask>
              <ode>
                <soft_cfm>0</soft_cfm>
                <soft_erp>0.2</soft_erp>
                <kp>1e+07</kp>
                <kd>1</kd>
                <max_vel>0.01</max_vel>
                <min_depth>0</min_depth>
              </ode>
              <bullet>
                <split_impulse>1</split_impulse>
                <split_impulse_penetration_threshold>-0.01</split_impulse_penetration_threshold>
                <soft_cfm>0</soft_cfm>
                <soft_erp>0.2</soft_erp>
                <kp>1e+07</kp>
                <kd>1</kd>
              </bullet>
            </contact>
          </surface>
        </collision>
        <self_collide>0</self_collide>
      </link>
      <frame name='wheel_front_right::__model__' attached_to='wheel_front_right::link_rim'>
        <pose relative_to='__model__'>0.118 -0.081 0 0 -0 0</pose>
      </frame>
      <link name='wheel_front_right::link_rim'>
        <inertial>
          <mass>0.038</mass>
          <inertia>
            <ixx>1.283e-05</ixx>
            <ixy>0</ixy>
            <ixz>0</ixz>
            <iyy>1.283e-05</iyy>
            <iyz>0</iyz>
            <izz>2.069e-05</izz>
          </inertia>
          <pose>0 0 0 0 -0 0</pose>
        </inertial>
        <pose relative_to='wheel_front_right::__model__'>0 0 0 1.5708 -0 0</pose>
        <gravity>1</gravity>
        <kinematic>0</kinematic>
        <enable_wind>0</enable_wind>
        <visual name='visual'>
          <pose>0 0 0 -1.5708 0 0</pose>
          <geometry>
            <mesh>
              <uri>model://wheel_right/meshes/rim.dae</uri>
              <scale>1 1 1</scale>
            </mesh>
          </geometry>
          <material>
            <lighting>1</lighting>
            <shader type='vertex'>
              <normal_map>__default__</normal_map>
            </shader>
            <ambient>0.2 0.2 0.2 1</ambient>
            <diffuse>0.3 0.3 0.3 1</diffuse>
            <specular>0.5 0.5 0.5 1</specular>
            <emissive>0 0 0 0</emissive>
          </material>
          <transparency>0</transparency>
          <cast_shadows>1</cast_shadows>
        </visual>
        <collision name='collision'>
          <laser_retro>0</laser_retro>
          <max_contacts>10</max_contacts>
          <pose>0 0 0 0 -0 0</pose>
          <geometry>
            <cylinder>
              <radius>0.033</radius>
              <length>0.028</length>
            </cylinder>
          </geometry>
          <surface>
            <friction>
              <ode>
                <mu>0.7</mu>
                <mu2>0.7</mu2>
                <fdir1>0 0 0</fdir1>
                <slip1>0</slip1>
                <slip2>0</slip2>
              </ode>
              <torsional>
                <coefficient>1</coefficient>
                <patch_radius>0</patch_radius>
                <surface_radius>0</surface_radius>
                <use_patch_radius>1</use_patch_radius>
                <ode>
                  <slip>0</slip>
                </ode>
              </torsional>
            </friction>
            <bounce>
              <restitution_coefficient>0</restitution_coefficient>
              <threshold>1e+06</threshold>
            </bounce>
            <contact>
              <collide_without_contact>0</collide_without_contact>
              <collide_without_contact_bitmask>1</collide_without_contact_bitmask>
              <collide_bitmask>1</collide_bitmask>
              <ode>
                <soft_cfm>0</soft_cfm>
                <soft_erp>0.2</soft_erp>
                <kp>1e+07</kp>
                <kd>1</kd>
                <max_vel>0.01</max_vel>
                <min_depth>0</min_depth>
              </ode>
              <bullet>
                <split_impulse>1</split_impulse>
                <split_impulse_penetration_threshold>-0.01</split_impulse_penetration_threshold>
                <soft_cfm>0</soft_cfm>
                <soft_erp>0.2</soft_erp>
                <kp>1e+07</kp>
                <kd>1</kd>
              </bullet>
            </contact>
          </surface>
        </collision>
        <self_collide>0</self_collide>
      </link>
      <frame name='camera::__model__' attached_to='camera::link_camera'>
        <pose relative_to='__model__'>0 0 0.2 0 0.2617 0</pose>
      </frame>
      <link name='camera::link_camera'>
        <inertial>
          <mass>0.0052875</mass>
          <inertia>
            <ixx>4.1e-07</ixx>
            <ixy>0</ixy>
            <ixz>0</ixz>
            <iyy>7.9e-07</iyy>
            <iyz>0</iyz>
            <izz>4.1e-07</izz>
          </inertia>
          <pose>0 0 0 0 -0 0</pose>
        </inertial>
        <pose relative_to='camera::__model__'>0 0 0 0 -0 0</pose>
        <gravity>1</gravity>
        <self_collide>0</self_collide>
        <kinematic>0</kinematic>
        <enable_wind>0</enable_wind>
        <visual name='visual'>
          <pose>0 0 0 0 -0 0</pose>
          <geometry>
            <box>
              <size>0.005 0.03 0.03</size>
            </box>
          </geometry>
          <material>
            <lighting>1</lighting>
            <script>
              <uri>file://media/materials/scripts/gazebo.material</uri>
              <name>Gazebo/Grey</name>
            </script>
            <shader type='vertex'>
              <normal_map>__default__</normal_map>
            </shader>
            <ambient>0.3 0.3 0.3 1</ambient>
            <diffuse>0.7 0.7 0.7 1</diffuse>
            <specular>0.01 0.01 0.01 1</specular>
            <emissive>0 0 0 1</emissive>
          </material>
          <transparency>0</transparency>
          <cast_shadows>1</cast_shadows>
        </visual>
        <collision name='collision'>
          <laser_retro>0</laser_retro>
          <max_contacts>10</max_contacts>
          <pose>0 0 0 0 -0 0</pose>
          <geometry>
            <box>
              <size>0.005 0.03 0.03</size>
            </box>
          </geometry>
          <surface>
            <friction>
              <ode>
                <mu>1</mu>
                <mu2>1</mu2>
                <fdir1>0 0 0</fdir1>
                <slip1>0</slip1>
                <slip2>0</slip2>
              </ode>
              <torsional>
                <coefficient>1</coefficient>
                <patch_radius>0</patch_radius>
                <surface_radius>0</surface_radius>
                <use_patch_radius>1</use_patch_radius>
                <ode>
                  <slip>0</slip>
                </ode>
              </torsional>
            </friction>
            <bounce>
              <restitution_coefficient>0</restitution_coefficient>
              <threshold>1e+06</threshold>
            </bounce>
            <contact>
              <collide_without_contact>0</collide_without_contact>
              <collide_without_contact_bitmask>1</collide_without_contact_bitmask>
              <collide_bitmask>1</collide_bitmask>
              <ode>
                <soft_cfm>0</soft_cfm>
                <soft_erp>0.2</soft_erp>
                <kp>1e+13</kp>
                <kd>1</kd>
                <max_vel>0.01</max_vel>
                <min_depth>0</min_depth>
              </ode>
              <bullet>
                <split_impulse>1</split_impulse>
                <split_impulse_penetration_threshold>-0.01</split_impulse_penetration_threshold>
                <soft_cfm>0</soft_cfm>
                <soft_erp>0.2</soft_erp>
                <kp>1e+13</kp>
                <kd>1</kd>
              </bullet>
            </contact>
          </surface>
        </collision>
        <sensor name='camera1' type='camera'>
          <update_rate>30</update_rate>
          <camera name='head'>
            <horizontal_fov>1.08559</horizontal_fov>
            <image>
              <width>640</width>
              <height>480</height>
              <format>R8G8B8</format>
            </image>
            <clip>
              <near>0.02</near>
              <far>100</far>
            </clip>
            <noise>
              <type>gaussian</type>
              <mean>0</mean>
              <stddev>0</stddev>
            </noise>
          </camera>
          <plugin name='camera_controller' filename='libgazebo_ros_camera.so'>
            <alwaysOn>1</alwaysOn>
            <updateRate>0.0</updateRate>
            <imageTopicName>image_raw</imageTopicName>
            <cameraInfoTopicName>camera_info</cameraInfoTopicName>
            <frameName>camera::link_camera</frameName>
            <hackBaseline>0.0</hackBaseline>
            <distortionK1>0.0</distortionK1>
            <distortionK2>0.0</distortionK2>
            <distortionK3>0.0</distortionK3>
            <distortionT1>0.0</distortionT1>
            <distortionT2>0.0</distortionT2>
            <robotNamespace>automobile</robotNamespace>
          </plugin>
        </sensor>
      </link>
      <frame name='car_body::__model__' attached_to='car_body::link'>
        <pose relative_to='__model__'>-0.024 0 -0.028 0 -0 0</pose>
      </frame>
      <link name='car_body::link'>
        <inertial>
          <mass>1</mass>
          <inertia>
            <ixx>0.166667</ixx>
            <ixy>0</ixy>
            <ixz>0</ixz>
            <iyy>0.166667</iyy>
            <iyz>0</iyz>
            <izz>0.166667</izz>
          </inertia>
          <pose>0 0 0 0 -0 0</pose>
        </inertial>
        <pose relative_to='car_body::__model__'>0 -0 0 0 -0 0</pose>
        <visual name='visual'>
          <pose>0 0 0 0 -0 0</pose>
          <geometry>
            <mesh>
              <uri>model://car_body/meshes/CarBody.dae</uri>
              <scale>1 1 1</scale>
            </mesh>
          </geometry>
          <material>
            <script>
              <uri>model://car_body/materials/scripts</uri>
              <uri>model://car_body/materials/textures</uri>
              <name>CarBody/Image</name>
            </script>
          </material>
          <transparency>0</transparency>
          <cast_shadows>1</cast_shadows>
        </visual>
        <self_collide>0</self_collide>
        <enable_wind>0</enable_wind>
        <kinematic>0</kinematic>
      </link>
      <static>0</static>
      <allow_auto_disable>1</allow_auto_disable>
      <frame name='lidar::__model__' attached_to='lidar::lidar_link'>
        <pose relative_to='__model__'>0.26 0 0.01 0 -0 0</pose>
      </frame>
      <link name='lidar::lidar_link'>
        <pose relative_to='lidar::__model__'>0 0 0 0 -0 0</pose>
        <inertial>
          <pose>0 0 0 0 -0 0</pose>
          <mass>0.001</mass>
          <inertia>
            <ixx>2.1733e-06</ixx>
            <ixy>0</ixy>
            <ixz>0</ixz>
            <iyy>2.1733e-06</iyy>
            <iyz>0</iyz>
            <izz>1.8e-07</izz>
          </inertia>
        </inertial>
        <visual name='visual'>
          <pose>0 0 0 0 -0 0</pose>
          <geometry>
            <cylinder>
              <radius>0.01</radius>
              <length>0.01</length>
            </cylinder>
          </geometry>
          <material>
            <script>
              <name>Gazebo/Green</name>
              <uri>__default__</uri>
            </script>
            <shader type='vertex'>
              <normal_map>__default__</normal_map>
            </shader>
          </material>
        </visual>
        <sensor name='laser' type='ray'>
          <ray>
            <scan>
              <horizontal>
                <samples>720</samples>
                <resolution>1</resolution>
                <min_angle>-1.57</min_angle>
                <max_angle>1.57</max_angle>
              </horizontal>
              <vertical>
                <samples>1</samples>
                <min_angle>0</min_angle>
                <max_angle>0</max_angle>
              </vertical>
            </scan>
            <range>
              <min>0.0</min>
              <max>2.2</max>
              <resolution>0.01</resolution>
            </range>
            <noise>
              <type>gaussian</type>
              <mean>0</mean>
              <stddev>0.02</stddev>
            </noise>
          </ray>
          <plugin name='LaserPlugin' filename='libgazebo_ros_laser.so'>
            <robotNamespace>automobile</robotNamespace>
            <topicName>scan</topicName>
            <frameName>automobile_lidar_lidar_link</frameName>
            <min_distance>0.0</min_distance>
            <max_distance>2.2</max_distance>
          </plugin>
          <always_on>1</always_on>
          <update_rate>20</update_rate>
          <visualize>1</visualize>
        </sensor>
        <self_collide>0</self_collide>
        <enable_wind>0</enable_wind>
        <kinematic>0</kinematic>
      </link>
      <joint name='joint_leftrear_rim' type='revolute'>
        <parent>chassis::link</parent>
        <child>wheel_rear_left::link_rim</child>
        <pose>0 0 0 0 -0 0</pose>
        <axis>
          <xyz>0 0 -1</xyz>
          <limit>
            <lower>-1.79769e+308</lower>
            <upper>1.79769e+308</upper>
            <effort>-1</effort>
            <velocity>-1</velocity>
          </limit>
          <dynamics>
            <spring_reference>0</spring_reference>
            <spring_stiffness>0</spring_stiffness>
            <damping>0</damping>
            <friction>0</friction>
          </dynamics>
        </axis>
        <physics>
          <ode>
            <limit>
              <cfm>0</cfm>
              <erp>0.2</erp>
            </limit>
            <suspension>
              <cfm>0</cfm>
              <erp>0.2</erp>
            </suspension>
          </ode>
        </physics>
      </joint>
      <joint name='joint_rightrear_rim' type='revolute'>
        <parent>chassis::link</parent>
        <child>wheel_rear_right::link_rim</child>
        <pose>0 0 0 0 -0 0</pose>
        <axis>
          <xyz>0 0 -1</xyz>
          <limit>
            <lower>-1.79769e+308</lower>
            <upper>1.79769e+308</upper>
            <effort>-1</effort>
            <velocity>-1</velocity>
          </limit>
          <dynamics>
            <spring_reference>0</spring_reference>
            <spring_stiffness>0</spring_stiffness>
            <damping>0</damping>
            <friction>0</friction>
          </dynamics>
        </axis>
        <physics>
          <ode>
            <limit>
              <cfm>0</cfm>
              <erp>0.2</erp>
            </limit>
            <suspension>
              <cfm>0</cfm>
              <erp>0.2</erp>
            </suspension>
          </ode>
        </physics>
      </joint>
      <joint name='joint_leftfront_steer' type='revolute'>
        <parent>chassis::link</parent>
        <child>steer_left::link_steer</child>
        <pose>0 0 0.005 0 -0 0</pose>
        <axis>
          <xyz>0 1 0</xyz>
          <limit>
            <lower>-1.79769e+308</lower>
            <upper>1.79769e+308</upper>
            <effort>-1</effort>
            <velocity>-1</velocity>
          </limit>
          <dynamics>
            <spring_reference>0</spring_reference>
            <spring_stiffness>0</spring_stiffness>
            <damping>0</damping>
            <friction>0</friction>
          </dynamics>
        </axis>
        <physics>
          <ode>
            <limit>
              <cfm>0</cfm>
              <erp>0.2</erp>
            </limit>
            <suspension>
              <cfm>0</cfm>
              <erp>0.2</erp>
            </suspension>
          </ode>
        </physics>
      </joint>
      <joint name='joint_rightfront_steer' type='revolute'>
        <parent>chassis::link</parent>
        <child>steer_right::link_steer</child>
        <pose>0 0 -0.005 0 -0 0</pose>
        <axis>
          <xyz>0 1 0</xyz>
          <limit>
            <lower>-1.79769e+308</lower>
            <upper>1.79769e+308</upper>
            <effort>-1</effort>
            <velocity>-1</velocity>
          </limit>
          <dynamics>
            <spring_reference>0</spring_reference>
            <spring_stiffness>0</spring_stiffness>
            <damping>0</damping>
            <friction>0</friction>
          </dynamics>
        </axis>
        <physics>
          <ode>
            <limit>
              <cfm>0</cfm>
              <erp>0.2</erp>
            </limit>
            <suspension>
              <cfm>0</cfm>
              <erp>0.2</erp>
            </suspension>
          </ode>
        </physics>
      </joint>
      <joint name='joint_rightfront_rim' type='revolute'>
        <parent>steer_right::link_steer</parent>
        <child>wheel_front_right::link_rim</child>
        <pose>0 0 0 0 -0 0</pose>
        <axis>
          <xyz>0 0 -1</xyz>
          <limit>
            <lower>-1.79769e+308</lower>
            <upper>1.79769e+308</upper>
            <effort>-1</effort>
            <velocity>-1</velocity>
          </limit>
          <dynamics>
            <spring_reference>0</spring_reference>
            <spring_stiffness>0</spring_stiffness>
            <damping>0</damping>
            <friction>0</friction>
          </dynamics>
        </axis>
        <physics>
          <ode>
            <limit>
              <cfm>0</cfm>
              <erp>0.2</erp>
            </limit>
            <suspension>
              <cfm>0</cfm>
              <erp>0.2</erp>
            </suspension>
          </ode>
        </physics>
      </joint>
      <joint name='joint_leftfront_rim' type='revolute'>
        <parent>steer_left::link_steer</parent>
        <child>wheel_front_left::link_rim</child>
        <pose>0 0 0 0 -0 0</pose>
        <axis>
          <xyz>0 0 -1</xyz>
          <limit>
            <lower>-1.79769e+308</lower>
            <upper>1.79769e+308</upper>
            <effort>-1</effort>
            <velocity>-1</velocity>
          </limit>
          <dynamics>
            <spring_reference>0</spring_reference>
            <spring_stiffness>0</spring_stiffness>
            <damping>0</damping>
            <friction>0</friction>
          </dynamics>
        </axis>
        <physics>
          <ode>
            <limit>
              <cfm>0</cfm>
              <erp>0.2</erp>
            </limit>
            <suspension>
              <cfm>0</cfm>
              <erp>0.2</erp>
            </suspension>
          </ode>
        </physics>
      </joint>
      <joint name='joint_body' type='fixed'>
        <parent>chassis::link</parent>
        <child>car_body::link</child>
        <pose>0 0 0 0 -0 0</pose>
        <physics>
          <ode>
            <limit>
              <cfm>0</cfm>
              <erp>0.2</erp>
            </limit>
            <suspension>
              <cfm>0</cfm>
              <erp>0.2</erp>
            </suspension>
          </ode>
        </physics>
      </joint>
      <joint name='joint_camera' type='fixed'>
        <parent>chassis::link</parent>
        <child>camera::link_camera</child>
        <pose>0 0 0 0 -0 0</pose>
        <physics>
          <ode>
            <limit>
              <cfm>0</cfm>
              <erp>0.2</erp>
            </limit>
            <suspension>
              <cfm>0</cfm>
              <erp>0.2</erp>
            </suspension>
          </ode>
        </physics>
      </joint>
      <joint name='lidar_joint' type='fixed'>
        <parent>chassis::link</parent>
        <child>lidar::lidar_link</child>
        <pose>0 0 0 0 -0 0</pose>
      </joint>
      <plugin name='CarLikeRobotPlugin' filename='libcar_plugin.so'>
        <wheelbase>0.26</wheelbase>
        <axletrack>0.162</axletrack>
        <wheelradius>0.0325</wheelradius>
        <speed_wheel_joints>
          <front_wheel_joints>
            <leftjoint>joint_leftfront_rim</leftjoint>
            <rightjoint>joint_rightfront_rim</rightjoint>
          </front_wheel_joints>
          <rear_wheel_joints>
            <leftjoint>joint_leftrear_rim</leftjoint>
            <rightjoint>joint_rightrear_rim</rightjoint>
          </rear_wheel_joints>
          <kp>0.01</kp>
          <ki>0.0</ki>
          <kd>0.0</kd>
        </speed_wheel_joints>
        <steer_wheel_joints>
          <leftjoint>joint_leftfront_steer</leftjoint>
          <rightjoint>joint_rightfront_steer</rightjoint>
          <kp>10</kp>
          <ki>0.0</ki>
          <kd>0.1</kd>
        </steer_wheel_joints>
        <initial_steer>0.0</initial_steer>
        <initial_speed>0.0</initial_speed>
        <robotNamespace>automobile</robotNamespace>
      </plugin>
      <plugin name='bno055' filename='libbno055_plugin.so'>
        <robotNamespace>/</robotNamespace>
      </plugin>
      <plugin name='gps' filename='libgps_plugin.so'>
        <robotNamespace>/</robotNamespace>
      </plugin>
      <pose>11.775 2.04 0.032939 0 -0 0</pose>
    </model>
    <state world_name='bfmc_official'>
      <sim_time>26 189000000</sim_time>
      <real_time>26 695028287</real_time>
      <wall_time>1717340482 824785491</wall_time>
      <iterations>26189</iterations>
      <model name='automobile'>
        <pose>11.777 2.03984 0.032939 -5.9e-05 0.00043 0.000564</pose>
        <scale>1 1 1</scale>
        <link name='camera::link_camera'>
          <pose>11.7771 2.03985 0.232938 -6.3e-05 0.262111 0.000548</pose>
          <velocity>0.000351 0.000166 -0.000953 -0.00371 0.013706 0.000199</velocity>
          <acceleration>0.108482 0.228263 -1.22733 -0.186358 0.114692 0.079039</acceleration>
          <wrench>0.000574 0.001207 -0.00649 0 -0 0</wrench>
        </link>
        <link name='car_body::link'>
          <pose>11.753 2.03983 0.004948 -6.2e-05 0.000464 0.000565</pose>
          <velocity>8.7e-05 -2.9e-05 -0.00084 -0.002523 0.000696 0.000162</velocity>
          <acceleration>-0.008531 -0.114223 -1.08244 -0.255396 0.485103 0.07821</acceleration>
          <wrench>-0.008531 -0.114223 -1.08244 0 -0 0</wrench>
        </link>
        <link name='chassis::link'>
          <pose>11.777 2.03984 0.032939 -5.9e-05 0.00043 0.000564</pose>
          <velocity>0.000105 3.9e-05 -0.000979 -0.0028 0.010263 0.0002</velocity>
          <acceleration>0.004041 -0.115177 -1.26171 -0.696784 1.32183 0.077735</acceleration>
          <wrench>0.001061 -0.030227 -0.331124 0 -0 0</wrench>
        </link>
        <link name='lidar::lidar_link'>
          <pose>12.037 2.03999 0.042808 -5.9e-05 0.000403 0.000564</pose>
          <velocity>0.000231 7.3e-05 -0.001838 -0.002794 0.012859 0.000276</velocity>
          <acceleration>0.181021 0.051063 -1.94812 -0.668672 -0.712324 -0.13794</acceleration>
          <wrench>0.000181 5.1e-05 -0.001948 0 -0 0</wrench>
        </link>
        <link name='steer_left::link_steer'>
          <pose>11.8889 2.1124 0.033006 1.57075 0.000366 0.00055</pose>
          <velocity>7.9e-05 0.000711 -0.035339 -0.006173 0.011723 0.004816</velocity>
          <acceleration>0.023997 0.886723 -49.2357 1.08903 -0.501776 2.65085</acceleration>
          <wrench>2.4e-05 0.000887 -0.049236 0 -0 0</wrench>
        </link>
        <link name='steer_right::link_steer'>
          <pose>11.889 1.96741 0.033043 1.57073 0.000409 0.0006</pose>
          <velocity>0.000123 -0.001119 0.00096 0.000397 -0.002657 0.000101</velocity>
          <acceleration>0.038954 -2.56616 2.01884 -0.098773 1.00819 -0.168548</acceleration>
          <wrench>3.9e-05 -0.002566 0.002019 0 -0 0</wrench>
        </link>
        <link name='wheel_front_left::link_rim'>
          <pose>11.8949 2.12091 0.032972 1.57079 0.021689 0.000536</pose>
          <velocity>3.9e-05 0.000573 -0.026279 -0.015822 -0.001386 0.008245</velocity>
          <acceleration>-0.001341 0.644894 -36.3541 -2.27931 -0.620586 1.49212</acceleration>
          <wrench>-5.1e-05 0.024506 -1.38146 0 -0 0</wrench>
        </link>
        <link name='wheel_front_right::link_rim'>
          <pose>11.895 1.95891 0.033 1.57079 0.066845 0.000604</pose>
          <velocity>0.000123 -0.000849 0.000639 0.025733 0.003745 -0.000222</velocity>
          <acceleration>0.031943 -2.0194 1.3507 -1.36412 0.793339 1.23158</acceleration>
          <wrench>0.001214 -0.076737 0.051327 0 -0 0</wrench>
        </link>
        <link name='wheel_rear_left::link_rim'>
          <pose>11.6249 2.12076 0.033 1.57081 0.059548 0.000564</pose>
          <velocity>9.3e-05 -0.000101 0.000413 0.003051 0.002817 7.1e-05</velocity>
          <acceleration>0.005725 -0.364141 0.851403 -0.956117 -1.13358 -0.300356</acceleration>
          <wrench>0.000218 -0.013837 0.032353 0 -0 0</wrench>
        </link>
        <link name='wheel_rear_right::link_rim'>
          <pose>11.625 1.95876 0.033 1.57079 0.070121 0.000564</pose>
          <velocity>0.000116 -1.1e-05 1.7e-05 0.000322 0.003507 5.8e-05</velocity>
          <acceleration>0.005429 -0.078795 0.055739 2.38801 -1.17628 -0.005491</acceleration>
          <wrench>0.000206 -0.002994 0.002118 0 -0 0</wrench>
        </link>
      </model>
      <model name='track'>
        <pose>10.34 6.87 0 0 -0 0</pose>
        <scale>1 1 1</scale>
        <link name='link'>
          <pose>10.34 6.87 0 0 -0 0</pose>
          <velocity>0 0 0 0 -0 0</velocity>
          <acceleration>0 0 0 0 -0 0</acceleration>
          <wrench>0 0 0 0 -0 0</wrench>
        </link>
      </model>
      <light name='c1'>
        <pose>0 0 2 0 -0 0</pose>
      </light>
      <light name='c2'>
        <pose>15 0 2 0 -0 0</pose>
      </light>
      <light name='c3'>
        <pose>0 -15 2 0 -0 0</pose>
      </light>
      <light name='c4'>
        <pose>15 -15 2 0 -0 0</pose>
      </light>
    </state>
    <gui fullscreen='0'>
      <camera name='user_camera'>
        <pose>12.4713 1.81472 7.78767 -3.6e-05 1.5698 1.5641</pose>
        <view_controller>orbit</view_controller>
        <projection_type>perspective</projection_type>
      </camera>
    </gui>
  </world>
</sdf>
